ITERATION NUMBER: 1
Current best mechanism: 
 [[-1  1  0  1  0]
 [ 0  1  0 -1  1]
 [ 0  1  1  0 -1]]
Current AIC value: 120.39225143846647
Previous best mechanism: 
 ['Nothing']
Previous AIC value: 1e+99
ITERATION NUMBER: 2
Current best mechanism: 
 [[-1  1  0  0  0  1]
 [ 0  1  0  1  0 -1]
 [ 0  0  1 -1  1  0]
 [ 0  1  0  0 -1  0]]
Current AIC value: 126.19029960985716
Previous best mechanism: 
 [[-1  1  0  1  0]
 [ 0  1  0 -1  1]
 [ 0  1  1  0 -1]]
Previous AIC value: 120.39225143846647
Exception in comm_msg for 186eb8184b5311ef9b78e2051eede723
Traceback (most recent call last):
  File "/Users/md1621/anaconda3/lib/python3.10/site-packages/spyder_kernels/comms/commbase.py", line 347, in _handle_remote_call
    self._set_call_return_value(msg_dict, return_value)
  File "/Users/md1621/anaconda3/lib/python3.10/site-packages/spyder_kernels/comms/commbase.py", line 384, in _set_call_return_value
    self._send_message('remote_call_reply', content=content, data=data,
  File "/Users/md1621/anaconda3/lib/python3.10/site-packages/spyder_kernels/comms/frontendcomm.py", line 113, in _send_message
    return super(FrontendComm, self)._send_message(*args, **kwargs)
  File "/Users/md1621/anaconda3/lib/python3.10/site-packages/spyder_kernels/comms/commbase.py", line 238, in _send_message
    raise CommError("The comm is not connected.")
spyder_kernels.comms.commbase.CommError: The comm is not connected.

During handling of the above exception, another exception occurred:

Traceback (most recent call last):
  File "/Users/md1621/anaconda3/lib/python3.10/site-packages/comm/base_comm.py", line 263, in comm_msg
    comm.handle_msg(msg)
  File "/Users/md1621/anaconda3/lib/python3.10/site-packages/spyder_kernels/comms/frontendcomm.py", line 260, in handle_msg
    comm._msg_callback(msg)
  File "/Users/md1621/anaconda3/lib/python3.10/site-packages/spyder_kernels/comms/commbase.py", line 333, in _comm_message
    self._message_handlers[spyder_msg_type](
  File "/Users/md1621/anaconda3/lib/python3.10/site-packages/spyder_kernels/comms/commbase.py", line 351, in _handle_remote_call
    self._set_call_return_value(msg_dict, exc_infos, is_error=True)
  File "/Users/md1621/anaconda3/lib/python3.10/site-packages/spyder_kernels/comms/commbase.py", line 384, in _set_call_return_value
    self._send_message('remote_call_reply', content=content, data=data,
  File "/Users/md1621/anaconda3/lib/python3.10/site-packages/spyder_kernels/comms/frontendcomm.py", line 113, in _send_message
    return super(FrontendComm, self)._send_message(*args, **kwargs)
  File "/Users/md1621/anaconda3/lib/python3.10/site-packages/spyder_kernels/comms/commbase.py", line 238, in _send_message
    raise CommError("The comm is not connected.")
spyder_kernels.comms.commbase.CommError: The comm is not connected.
